package exception_handling;
public class TryCatch1 {
    public static void main(String[] args) {
        System.out.println("inside main method");
        int a=32;
        int b=0;
        
        int c;
        
        c=a/b;
        System.out.println("value of c is : "+c);
        
        System.out.println("end of main method");
    }
  
}
